Workbook

Sheet Inputs
A1: Watch Power Calculator - change the yellow cells (blue text)
A2: Yellow cells with blue text are inputs you can change. Every other number in this workbook is a formula and updates automatically. VERIFIED = from a datasheet; ESTIMATE = my assumption, so please change it if you know better.
A4: 1. Battery
A5: Battery nominal voltage | B5: 3.7 | C5: V | D5: LiPo nominal voltage (3.0-4.2 V in use). ESTIMATE of the average.
A6: Battery capacity | B6: =INDEX(Batteries!$B$6:$E$6,MATCH(B59,Batteries!$B$4:$E$4,0)) | C6: mAh | D6: Comes from the battery you pick in row 59 (Batteries tab). To use a different cell, edit the capacity on the Batteries tab.
A7: Battery energy | B7: =B5*B6 | C7: mWh | D7: Formula: voltage x capacity.
A8: Battery self-discharge per month | B8: 0.02 | C8: fraction | D8: ESTIMATE: 2%/month (LiPo is typically 1-5%).
A10: 2. White LED electrical (one series resistor value for all columns)
A11: Series resistor in each column | B11: 150 | C11: ohm | D11: PLACEHOLDER in the schematic (R1-R12 = 150 ohm). White LEDs need ~2.7+ V, so this value sets the brightness.
A12: Voltage lost in the MCU pins (high-side + low-side) | B12: 0.5 | C12: V | D12: Worst case from the datasheets: AVR128DB sink 0.6 V at 10 mA and source 0.7 V at 6 mA, so about 0.2 V + 0.4 V = 0.6 V at 3-4 mA. Typical is lower; 0.5 V used. The old 0.3 V was optimistic.
A13: OPTIONAL: force an LED on-current (leave blank to calculate) | C13: mA | D13: If you type a number here it replaces the calculated on-current for every LED.
D14: On-current = (battery V - LED Vf - pin drop) / resistor. Vf per LED type is on the 'LED types' tab.
A15: 3. Multiplexing and PWM dimming
A16: Rows scanned in turn while the display is on | B16: 3 | C16: rows | D16: 3 when you show an hour + a minute + a second LED (they are always in different rows). Each LED then gets 1/3 of the time.
A17: PWM duty - Hour LED | B17: 0.2 | C17: of slot | D17: PWM duty = how much of its time slot the LED is actually on. 100% = full brightness for the slot, 20% = dim.
A18: PWM duty - Minute LED | B18: 0.2 | C18: of slot | D18: Brightness and energy both follow the AVERAGE current, so halving the duty halves both.
A19: PWM duty - Second LED | B19: 0.2 | C19: of slot | D19: Default 20% gives ~0.3 mA average per LED (dim but visible indoors).
A21: 4. The time being shown, and how often
A22: Hour shown (1-12) | B22: 10 | D22: These three pick which LEDs are lit on the 'Every LED' tab.
A23: Minute shown (0-59) | B23: 8
A24: Second shown (0-59) | B24: 42
A25: Seconds the display stays on after each wake | B25: 3 | C25: s
A26: Wakes per day (gesture or button) | B26: 60 | C26: per day | D26: 20 = rarely, 60 = a few times an hour, 200 = checking constantly.
A27: MCU current while the display is up | B27: 1.5 | C27: mA | D27: ESTIMATE; depends on clock speed (AVR128DB data sheet gives the curve).
A29: 5. Always-on draw (the watch waiting to be woken)
A30: MCU deep sleep with 32.768 kHz clock running | B30: 3.3 | C30: uA | D30: Derived from the AVR128DB data sheet (power-down 0.65 uA + RTC/crystal ~2.6 uA); not a printed figure.
A31: 3.3 V regulator quiescent current | B31: 1.6 | C31: uA | D31: VERIFIED: MCP1700 data sheet (Variant A). The BQ25570 buck (Variant B) is similar or lower.
A32: How the watch is woken (pick from the list) | B32: LIS2DW12 accelerometer wake | D32: Button only = nothing running. BMI270 = the 6-axis sensor in wake-on-motion. BMA400 = a simpler accelerometer.
A33: Custom wake sensor current (used only if you pick Custom) | B33: 5 | C33: uA
A34: Custom wake sensor supply voltage | B34: 3.3 | C34: V
A36: 6. Solar (optional)
A37: Solar cell (pick from the list) | B37: KXOB25-07X1TF
A38: Wearer profile (pick from the list) | B38: Commuter
A39: Wrist factor (face tilted, sleeve shade) | B39: 0.5 | D39: ESTIMATE (research report: wrist reads under half of eye-level light).
A40: Optical / area factor (bezel, glass, LED rings) | B40: 0.85 | D40: ESTIMATE.
A41: Harvester IC efficiency | B41: 0.75 | D41: ESTIMATE; real harvesters do worse at microwatt levels.
A42: Charge efficiency into the battery | B42: 0.95 | D42: ESTIMATE.
A44: 7. Special mode: fluid / gravity / tilt game (optional, a minute or two a day)
A45: Minutes of special mode per day | B45: 2 | C45: min
A46: LEDs lit at once (average) while playing | B46: 40 | C46: LEDs | D46: A 'liquid' filling about a third of the face = ~40 LEDs.
...

Sheet LEDs
A1: LED catalog: white options for the clock face, and the RGB parts from the first design
A2: Prices, stock and links checked live on 2026-10-08 (DigiKey, JLCPCB) unless marked. VERIFIED = read from the distributor page or datasheet; ESTIMATE/UNVERIFIED = not confirmed. Pad length/width come from KiCad's stock footprints and drive the ring-size calculator on the 'Board size' tab. The first six columns can be picked on the Inputs tab.
A4: Attribute | B4: 0201 white - Xinglight XL-0201UWC | C4: 0402 white - Xinglight XL-1005UWC | D4: 0603 white - Kento KT-0603W | E4: 0603 white - Dialight 5973904507F (DigiKey alt) | F4: 0805 white - Kento KT-0805W | G4: 0805 white - Lite-On LTW-170TK (DigiKey alt) | H4: RGB 0.83 mm - Harvatek B39D3RGB (original design) | I4: RGB 0.8 mm - Meihua MHPA0808RGBDT (JLCPCB alt)
A5: Role / why it is here | B5: Option: smallest white LED (0201). Hardest to place and inspect. | C5: Option: small white LED for the second and minute rings (0402). | D5: CURRENT DESIGN default for the hour ring (0603). | E5: DigiKey stand-in for the 0603 white LED (not the same part). | F5: CURRENT DESIGN option for the hour ring if you want it brighter/larger (0805). | G5: DigiKey stand-in for the 0805 white LED (the 4th size). | H5: RGB LED from the first (RGB) watch design. | I5: JLCPCB's in-stock stand-in for the RGB LED (common ANODE).
A6: Colour | B6: White (cool) | C6: White (cool) | D6: White | E6: White | F6: White | G6: White | H6: Red / green / blue | I6: Red / green / blue
A7: Package | B7: 0201 (0603 metric) | C7: 0402 (1005 metric) | D7: 0603 (1608 metric) | E7: 0603 (1608 metric) | F7: 0805 (2012 metric) | G7: 0805 (2012 metric) | H7: 0.83 x 0.83 mm, 4 pads | I7: 0.8 x 0.8 mm, 4 pads
A8: Body size (mm) | B8: 0.65 x 0.35 | C8: 1.10 x 0.55 | D8: 1.6 x 0.8 | E8: 1.6 x 0.8 | F8: 2.0 x 1.25 | G8: 2.0 x 1.25 | H8: 0.83 x 0.83 | I8: 0.8 x 0.8
A9: Pad-axis length (mm, KiCad footprint) | B9: 1.1 | C9: 1.56 | D9: 2.45 | E9: 2.45 | F9: 2.85 | G9: 2.85 | H9: n/a | I9: n/a
A10: Pad width (mm, KiCad footprint) | B10: 0.4 | C10: 0.64 | D10: 0.95 | E10: 0.95 | F10: 1.4 | G10: 1.4 | H10: n/a | I10: n/a
A11: Height max (mm) | B11: 0.65 | C11: 0.7 | D11: 0.65 | E11: 0.65 | F11: 0.8 | G11: 0.8 | H11: 0.75 | I11: 0.6
A12: Forward voltage typ (V) | B12: 2.7 | C12: 2.8 | D12: 2.85 | E12: 2.9 | F12: 2.9 | G12: 3.3 | H12: 2.5 | I12: 2.5
A13: Test current for brightness (mA) | B13: 5 | C13: 20 | D13: 5 | E13: 20 | F13: 5 | G13: 20 | H13: 5 | I13: 3
A14: Brightness at test current (mcd) | B14: 185 | C14: 690 | D14: 250 | E14: 120 | F14: 250 | G14: 281 | H14: R 26 / G 37 / B 7.5 | I14: R 16-28 / G 28-47 / B 7.5-12.6
A15: Viewing angle (deg) | B15: 120 | C15: 120 | D15: 120 | E15: n/a | F15: 120 | G15: n/a | H15: 140 | I15: 120
A16: Configuration | B16: Single LED, 2 pads | C16: Single LED, 2 pads | D16: Single LED, 2 pads | E16: Single LED, 2 pads | F16: Single LED, 2 pads | G16: Single LED, 2 pads | H16: Common CATHODE | I16: Common ANODE
A17: DigiKey part number | B17: 5962-XL-0201UWCTR-ND | C17: 5962-XL-1005UWCTR-ND | D17: Not sold by DigiKey | E17: 350-4383-2-ND | F17: Not sold by DigiKey | G17: 160-1738-2-ND | H17: 3147-B39D3RGB-F6C0001HOU1930CT-ND | I17: Not checked at DigiKey
A18: DigiKey stock | B18: 100000 | C18: 100000 | D18: n/a | E18: 2053 | F18: n/a | G18: 155071 | H18: 20772 | I18: n/a
A19: DigiKey unit price at the minimum order (USD) | B19: 0.09375 | C19: 0.01563 | D19: n/a | E19: 0.62 | F19: n/a | G19: 0.5 | H19: 0.4 | I19: n/a
A20: DigiKey unit price at ~100 (USD) | B20: n/a | C20: n/a | D20: n/a | E20: 0.3103 | F20: n/a | G20: 0.2476 | H20: 0.1969 | I20: n/a
A21: DigiKey minimum order (pieces) | B21: 5000 | C21: 5000 | D21: n/a | E21: 1 | F21: n/a | G21: 1 | H21: 1 | I21: n/a
A22: DigiKey cost of one minimum order (USD) | B22: =IF(AND(ISNUMBER(B19),ISNUMBER(B21)),B19*B21,"n/a") | C22: =IF(AND(ISNUMBER(C19),ISNUMBER(C21)),C19*C21,"n/a") | D22: =IF(AND(ISNUMBER(D19),ISNUMBER(D21)),D19*D21,"n/a") | E22: =IF(AND(ISNUMBER(E19),ISNUMBER(E21)),E19*E21,"n/a") | F22: =IF(AND(ISNUMBER(F19),ISNUMBER(F21)),F19*F21,"n/a") | G22: =IF(AND(ISNUMBER(G19),ISNUMBER(G21)),G19*G21,"n/a") | H22: =IF(AND(ISNUMBER(H19),ISNUMBER(H21)),H19*H21,"n/a") | I22: =IF(AND(ISNUMBER(I19),ISNUMBER(I21)),I19*I21,"n/a")
A23: DigiKey link | B23: DigiKey page | C23: DigiKey page | D23: - | E23: DigiKey page | F23: - | G23: DigiKey page | H23: DigiKey page | I23: -
A24: JLCPCB / LCSC part | B24: C965789 | C24: C20613596 | D24: C2290 | E24: n/a | F24: C34499 | G24: n/a | H24: C6509069 | I24: C404279
A25: JLCPCB library type (Basic = no extra fee) | B25: Extended | C25: Extended | D25: Basic | E25: n/a | F25: Basic | G25: n/a | H25: Extended | I25: Extended
A26: JLCPCB stock | B26: 7966 | C26: 337280 | D26: 2096313 | E26: n/a | F26: 482058 | G26: n/a | H26: 0 | I26: 14075
A27: JLCPCB unit price at low quantity (USD) | B27: 0.07 | C27: 0.0113 | D27: 0.0122 | E27: n/a | F27: 0.0202 | G27: n/a | H27: n/a | I27: 0.0472
A28: JLCPCB link | B28: JLCPCB page | C28: JLCPCB page | D28: JLCPCB page | E28: - | F28: JLCPCB page | G28: - | H28: JLCPCB page | I28: JLCPCB page
A29: Datasheet | B29: datasheet / listing | C29: datasheet / listing | D29: datasheet / listing | E29: datasheet / listing | F29: datasheet / listing | G29: datasheet / listing | H29: datasheet / listing | I29: datasheet / listing
A30: Status | B30: Active | C30: Active | D30: Active | E30: Active | F30: Active | G30: Active | H30: OBSOLETE (stocked until sold out) | I30: Active
A31: Cost of the 132 LEDs at DigiKey price (USD) | B31: =IF(ISNUMBER(B20),B20*132,IF(ISNUMBER(B19),B19*132,"n/a")) | C31: =IF(ISNUMBER(C20),C20*132,IF(ISNUMBER(C19),C19*132,"n/a")) | D31: =IF(ISNUMBER(D20),D20*132,IF(ISNUMBER(D19),D19*132,"n/a")) | E31: =IF(ISNUMBER(E20),E20*132,IF(ISNUMBER(E19),E19*132,"n/a")) | F31: =IF(ISNUMBER(F20),F20*132,IF(ISNUMBER(F19),F19*132,"n/a")) | G31: =IF(ISNUMBER(G20),G20*132,IF(ISNUMBER(G19),G19*132,"n/a")) | H31: =IF(ISNUMBER(H20),H20*132,IF(ISNUMBER(H19),H19*132,"n/a")) | I31: =IF(ISNUMBER(I20),I20*132,IF(ISNUMBER(I19),I19*132,"n/a"))
A32: Cost of the 132 LEDs at JLCPCB price (USD) | B32: =IF(ISNUMBER(B27),B27*132,"n/a") | C32: =IF(ISNUMBER(C27),C27*132,"n/a") | D32: =IF(ISNUMBER(D27),D27*132,"n/a") | E32: =IF(ISNUMBER(E27),E27*132,"n/a") | F32: =IF(ISNUMBER(F27),F27*132,"n/a") | G32: =IF(ISNUMBER(G27),G27*132,"n/a") | H32: =IF(ISNUMBER(H27),H27*132,"n/a") | I32: =IF(ISNUMBER(I27),I27*132,"n/a")
A33: Lowest battery voltage at which it lights (Vf + pin drop) | B33: =IF(ISNUMBER(B12),B12+Inputs!$B$12,"n/a") | C33: =IF(ISNUMBER(C12),C12+Inputs!$B$12,"n/a") | D33: =IF(ISNUMBER(D12),D12+Inputs!$B$12,"n/a") | E33: =IF(ISNUMBER(E12),E12+Inputs!$B$12,"n/a") | F33: =IF(ISNUMBER(F12),F12+Inputs!$B$12,"n/a") | G33: =IF(ISNUMBER(G12),G12+Inputs!$B$12,"n/a") | H33: =IF(ISNUMBER(H12),H12+Inputs!$B$12,"n/a") | I33: =IF(ISNUMBER(I12),I12+Inputs!$B$12,"n/a")
A34: Shortcomings | B34: Tiny: hardest to place and rework. DigiKey sells it only as a 5,000-piece reel (marketplace, ships from the maker). 185 mcd at 5 mA is dim at the 0.3 mA we plan to use. Only ~8,000 at JLCPCB (Extended part: extra fee). | C34: DigiKey: reel of 5,000 only (marketplace). JLCPCB has two listings of this part number; the other (C965796) shows 0 stock. Datasheet brightness spread is wide (350-1000 mcd at 20 mA); the DigiKey page says 690. | D34: Not on DigiKey (JLCPCB/LCSC only). Brightness varies a lot unit to unit (145-360 mcd at 5 mA; JLCPCB lists up to 360). Vf range 2.6-3.1 V. Height is an estimate. | E34: About 25x the price of the Kento 0603 ($0.31 vs ~$0.012). Only 2,053 in stock, 12-week lead time. Test current for the 120 mcd rating is not confirmed. | F34: Not on DigiKey. Conflicting brightness data: the datasheet says 145-360 mcd at 5 mA, JLCPCB's listing says 350 mcd at 25 mA. The 0805 is the largest ring part, so it sets the board size. | G34: Highest forward voltage (3.3 V): on a LiPo it needs ~3.6 V before it lights at all, so it goes dark long before the battery is empty. ~12x the price of the Kento 0805. | H34: Obsolete at DigiKey. Zero stock at JLCPCB. 0.3 mm pads on a 0.5 mm pitch cannot be hand-soldered. Vf R 1.9 / G 2.5 / B 2.5 V. | I34: Common-anode (the first design is common-cathode), so matrix drive polarity must be reversed. Vf up to 3.5 V for green/blue. Same 0.5 mm pad pitch: still needs a fab to place.
A35: How well verified | B35: DigiKey page VERIFIED (price, stock, Vf 2.7 V, 185 mcd). 5 mA test current from a search summary. Height 0.65 mm UNVERIFIED. | C35: DigiKey and JLCPCB pages VERIFIED. Datasheet range from the earlier research report (LCSC PDF). | D35: JLCPCB page VERIFIED (stock, price, Basic). Vf/brightness from the JLCPCB listing and the earlier research report. Height ESTIMATE. | E35: DigiKey page VERIFIED (price, stock, 2.9 V, 120 mcd). Test current 20 mA is an ESTIMATE; height ESTIMATE. | F35: JLCPCB page VERIFIED (stock, price, Basic). Brightness conflict flagged. Height ESTIMATE. | G35: DigiKey page VERIFIED (price, stock, 3.3 V, 281 mcd, datasheet link). Test current 20 mA and height are ESTIMATES. | H35: DigiKey page VERIFIED on 2026-10-06 (20,772 in stock). JLCPCB stock 0 as of 2026-10-05. Test current ~5.2 mA from the part alias (UNVERIFIED). | I35: JLCPCB page VERIFIED (stock, price). Datasheet figures from the earlier JLCPCB research report.

Sheet Sensors
A1: Motion sensors: the two being compared, plus a backup
A2: Checked 2026-10-08. A gravity / tilt game only needs an accelerometer; the gyroscope in the BMI270 is not needed for it. Currents are at the supply voltages in the datasheets (BMI270 table: VDD = 1.8 V), so real values at 3.3 V are a little different.
A4: Attribute | B4: BMI270 (Bosch, 6-axis IMU) | C4: BMA400 (Bosch, accelerometer) | D4: LIS2DW12 (ST, accelerometer) - CURRENT PICK
A5: Type | B5: 6-axis IMU (accelerometer + gyroscope) | C5: 3-axis accelerometer (no gyroscope) | D5: 3-axis accelerometer (no gyroscope)
A6: Package / body (mm) | B6: LGA-14, 2.5 x 3.0 x 0.83 | C6: LGA-12, 2.0 x 2.0 x 0.95 | D6: LGA-12, 2.0 x 2.0 x 0.7 max
A7: KiCad courtyard width (mm) | B7: 3.79 | C7: 2.59 | D7: 2.59
A8: KiCad courtyard height (mm) | B8: 3.29 | C8: 2.59 | D8: 2.59
A9: Supply range | B9: VDD 1.71-3.6 V | C9: VDD 1.71-3.6 V (DigiKey page) | D9: VDD 1.62-3.6 V, separate VDD_IO 1.62 V to VDD+0.1 V
A10: Needs a configuration file loaded at every power-up? | B10: YES: an 8 KB file every power-up (about 6.6 ms at 10 MHz SPI, then up to 20 ms wait) | C10: No (boots by itself) | D10: No (boots by itself)
A11: Built-in features | B11: Wrist-wear wake-up, wrist gesture, any-motion, no-motion, significant motion, step counting | C11: Wake-up, activity change, orientation, tap, step counter | D11: Wake-up, activity/inactivity, free-fall, 6D/4D orientation, single/double tap, stationary/motion detect, 32-level FIFO, temperature sensor
A12: Sleep / suspend current (uA) | B12: 3.5 | C12: 0.16 | D12: 0.05
A13: Waiting for motion, lowest-power mode (uA) | B13: 10 | C13: 0.85 | D13: 1
A14: Wake-on-motion total used in the model (uA) | B14: 13 | C14: 0.85 | D14: 1
A15: Running a game, accelerometer only (uA) | B15: 210 | C15: 14.5 | D15: 5
A16: Running a game, accelerometer + gyroscope (uA) | B16: 685 | C16: n/a | D16: n/a
A17: DigiKey part number | B17: 828-1091-2-ND | C17: 828-1081-2-ND | D17: 497-17718-2-ND
A18: DigiKey stock (US) | B18: 50792 | C18: 0 | D18: 0
A19: DigiKey price at 1 (USD) | B19: 4.23 | C19: 2.48 | D19: 1.38
A20: DigiKey lead time | B20: 16 weeks | C20: 16 weeks | D20: 20 weeks
A21: DigiKey link | B21: link | C21: link | D21: link
A22: JLCPCB / LCSC part | B22: C2836813 | C22: not checked | D22: C189624
A23: JLCPCB library type | B23: Extended | C23: - | D23: Extended
A24: JLCPCB stock | B24: 7628 | C24: n/a | D24: 19750
A25: JLCPCB price at low quantity (USD) | B25: 2.64 | C25: n/a | D25: 1.19
A26: JLCPCB link | B26: link | C26: - | D26: link
A27: Datasheet | B27: link | C27: link | D27: link
A28: Status | B28: Active | C28: Active | D28: Active
A29: Shortcomings | B29: Wake mode costs ~13 uA all day (~1 mWh/day, about half the whole watch). Needs the 8 KB config upload at every power-up. 0.5 mm 14-pad LGA: the biggest sensor footprint. Costs ~$4 each. | C29: ZERO stock at DigiKey US on every listing (checked three). No gyroscope, so no rotation games. Not checked at JLCPCB. No built-in wrist-gesture classifier: raise-to-wake needs more firmware. | D29: Zero stock at DigiKey US (20-week lead time), but 19,712 at JLCPCB for $1.19. Datasheet DS11811 rev 9 is saved in datasheets/. Interrupt output only reaches VDD_IO - 0.2 V (~3.1 V): the MCU input must be set to TTL level. Low-power-mode figures are at 1.8 V.
A30: How well verified | B30: Datasheet currents VERIFIED (BST-BMI270-DS000-08, Table 6 and electrical table). DigiKey and JLCPCB pages VERIFIED. | C30: Currents VERIFIED by the earlier research (BST-BMA400-DS000-09). DigiKey pages VERIFIED today (stock 0, $2.48). | D30: VERIFIED: ST datasheet DS11811 rev 9 (Table 4: 50 nA power-down, 1 uA @12.5 Hz, 0.38 uA @1.6 Hz, 5 uA @100 Hz low-power mode 1, 90 uA high-performance). DigiKey/JLCPCB pages VERIFIED.

Sheet MCUs
A1: Microcontroller comparison: one for the single-colour watch, one for the RGB watch
A2: Pin counts, limits and pin maps are from the datasheets saved in datasheets/ (AVR128DB DS40002247B; ATmega169P doc8018P: the 169P edition, the PA edition could not be downloaded). Stock/price from JLCPCB 2026-10-08.
A4: Attribute | B4: AVR128DB48 (single colour - CURRENT PICK) | C4: ATmega169PA (RGB - CURRENT PICK) | D4: AVR128DB64 (RGB alternative) | E4: ATmega1284P (single colour backup)
A5: Package / body | B5: TQFP-48 7x7 (or VQFN-48 6x6) | C5: TQFP-64 14x14 (or QFN-64 9x9) | D5: QFN-64 9x9 (TQFP-64 10x10: 0 stock) | E5: TQFP-44 10x10
A6: Usable GPIO after crystal/reset/programming pins | B6: 38 | C6: 53 | D6: 53 | E6: 32
A7: GPIO this watch needs (matrix + extras) | B7: 29 | C7: 48 | D7: 48 | E7: 29
A8: Spare GPIO | B8: =B6-B7 | C8: =C6-C7 | D8: =D6-D7 | E8: =E6-E7
A9: Sink current guaranteed per pin at 3 V (mA) | B9: 10 | C9: 5 (Port B: 10) | D9: 10 | E9: n/a (not read)
A10: Source current guaranteed per pin at 3 V (mA) | B10: 6 | C10: 5 (Port B: 10) | D10: 6 | E10: n/a (not read)
A11: Absolute maximum per pin (mA) | B11: 50 | C11: 40 | D11: 50 | E11: n/a (not read)
A12: Sleep with 32 kHz crystal running (uA, typ) | B12: about 3 (0.65 power-down + ~2.1 RTC) | C12: 0.8 | D12: about 3 | E12: n/a (not read)
A13: Programming | B13: UPDI (1 pin) | C13: ISP/JTAG (shares row pins) | D13: UPDI | E13: ISP
A14: Max clock at 3-4.2 V | B14: 24 MHz | C14: 8 MHz | D14: 24 MHz | E14: n/a (not read)
A15: 32 kHz crystal pins | B15: PF0/PF1 (GPIO lost) | C15: pins 23/24 (dedicated XTAL1/XTAL2) | D15: PF0/PF1 | E15: n/a (not read)
A16: Pin-change / wake limits | B16: any pin (LEVEL or BOTHEDGES) | C16: PB, PE (PCINT) and PD1 (INT0) only | D16: any pin | E16: n/a (not read)
A17: Hazards found in the datasheet | B17: Port C powered from VDDIO2 (tie to VDD, set fuse); INT input needs TTL level | C17: JTAG fuse on at the factory (PF4-PF7); crystal must be on pins 23/24 | D17: same as AVR128DB48 | E17: not read
A18: JLCPCB part / stock / price | B18: C1019766 / 60 / $5.38 | C18: C9434 / 170 / $4.87 (also C507109 / 226 / $4.02) | D18: C1019767 / 11 / $5.55 | E18: C33575 / 1,943 / $6.59
A19: DigiKey stock | B19: 217 (AVR128DB48-I/PT) | C19: not checked | D19: not checked | E19: not checked
A20: Datasheet in folder | B20: yes: datasheets/AVR128DB28-32-48-64-DS40002247B.pdf | C20: 169P edition only (PA not downloadable) | D20: same as AVR128DB48 | E20: no
A21: Why pick it / why not | B21: UPDI, 1 pin to program, low sleep, enough pins. Weakness: low JLCPCB stock (60). | C21: Low sleep (0.8 uA), JLCPCB stocked, same family as the first board. Weakness: 14x14 mm body, 5 mA/pin on most ports. | D21: Same family as the single-colour chip; stock only 11. | E21: Big body, almost no spare pins, ISP.
A22: Row-pin check: single colour game mode (12 LEDs in one row, 'Power budget' tab uses the same peak current)
A23: Peak current per lit LED (mA) | B23: =AVERAGE('LED types'!F5:F7)
A24: Sink current if all 12 LEDs of a row are lit at once (mA) | B24: =12*B23
A25: Guaranteed sink current per pin (mA) | B25: =B9
A26: Most LEDs per slot a pin can take (software scheduling) | B26: =MAX(1,INT(B25/B23))
A27: Verdict | B27: =IF(B24<=B25,"OK without drivers","TOO MUCH for one pin: schedule "&B26&" LEDs per slot (dimmer game) or add row driver transistors")

Sheet Batteries
A1: Battery options (single-cell protected LiPo, wire leads, soldered to the back of the board)
A2: Mouser prices/stock checked 2026-10-08. All four are Renata ICP cells (3.7 V). Runtime rows use the live load from the 'Power budget' tab, so they change when you change the inputs. Other cheaper LiPo cells exist (hobby vendors) but their protection circuits and dimensions are unverified.
A4: Attribute | B4: Renata ICP341018PM (35 mAh) | C4: Renata ICP331319PM (50 mAh) | D4: Renata ICP501022UPM (80 mAh) | E4: Renata ICP402025PC-01 (155 mAh)
A5: Manufacturer part number | B5: ICP341018PM | C5: ICP331319PM | D5: ICP501022UPM | E5: ICP402025PC-01
A6: Capacity (mAh) | B6: 35 | C6: 50 | D6: 80 | E6: 155
A7: Nominal voltage (V) | B7: 3.7 | C7: 3.7 | D7: 3.7 | E7: 3.7
A8: Energy (mWh) | B8: =B6*B7 | C8: =C6*C7 | D8: =D6*D7 | E8: =E6*E7
A9: Length (mm) | B9: 19.5 | C9: 21 | D9: 24 | E9: 27.5
A10: Width (mm) | B10: 10.2 | C10: 12.8 | D10: 10 | E10: 20.5
A11: Thickness max (mm, includes swelling) | B11: 3.7 | C11: 3.7 | D11: 5.5 | E11: 4.3
A12: Footprint area (mm2) | B12: =B9*B10 | C12: =C9*C10 | D12: =D9*D10 | E12: =E9*E10
A13: Volume (cm3) | B13: =B12*B11/1000 | C13: =C12*C11/1000 | D13: =D12*D11/1000 | E13: =E12*E11/1000
A14: Energy density (mWh per cm3) | B14: =B8/B13 | C14: =C8/C13 | D14: =D8/D13 | E14: =E8/E13
A15: Diagonal (mm) | B15: =SQRT(B9^2+B10^2) | C15: =SQRT(C9^2+C10^2) | D15: =SQRT(D9^2+D10^2) | E15: =SQRT(E9^2+E10^2)
A16: Weight (g) | B16: 1.7 | C16: 2 | D16: 2.6 | E16: 4
A17: Protection circuit | B17: Yes (safety circuit) | C17: Yes (safety circuit) | D17: Yes (IEC62133 per search excerpt) | E17: Yes (per datasheet excerpt)
A18: Maximum charge current | B18: 17.5 mA normal / 35 mA max (0.5C / 1C) | C18: 25 mA normal / 50 mA max | D18: 40 mA normal / 80 mA max | E18: 155 mA max
A19: Termination | B19: AWG30 wire leads | C19: AWG30 wire leads | D19: Wire leads | E19: PC-01 connector version
A20: Temperature limits | B20: Charge 0 to 45 C | C20: Charge 0 to 45 C | D20: Charge 0 to 45 C | E20: Charge 0 to 45 C
A21: Mouser part number | B21: 614-ICP341018PM | C21: 614-ICP331319PM | D21: 614-ICP501022UPM | E21: 614-ICP402025PC-01
A22: Mouser stock | B22: 0 | C22: 0 | D22: 3 | E22: 0
A23: Mouser price at 1 (USD) | B23: 13.87 | C23: 12.21 | D23: 12.22 | E23: 12.84
A24: Mouser price at 100 (USD) | B24: 9.6 | C24: 8.46 | D24: 8.46 | E24: 8.89
A25: Mouser link | B25: Mouser page | C25: Mouser page | D25: Mouser page | E25: Mouser page
A26: Datasheet | B26: datasheet | C26: datasheet | D26: datasheet | E26: datasheet
A27: Price per mWh at 1 (USD) | B27: =B23/B8 | C27: =C23/C8 | D27: =D23/D8 | E27: =E23/E8
A28: Runtime with no solar, current inputs (days) | B28: =IF('Power budget'!$B$22>0,B8/'Power budget'!$B$22,0) | C28: =IF('Power budget'!$B$22>0,C8/'Power budget'!$B$22,0) | D28: =IF('Power budget'!$B$22>0,D8/'Power budget'!$B$22,0) | E28: =IF('Power budget'!$B$22>0,E8/'Power budget'!$B$22,0)
A29: Runtime including special mode (days) | B29: =IF('Power budget'!$B$61>0,B8/'Power budget'!$B$61,0) | C29: =IF('Power budget'!$B$61>0,C8/'Power budget'!$B$61,0) | D29: =IF('Power budget'!$B$61>0,D8/'Power budget'!$B$61,0) | E29: =IF('Power budget'!$B$61>0,E8/'Power budget'!$B$61,0)
A30: Fits inside the board size calculated on 'Board size'? | B30: =IF('Board size'!$B$33>=B15+2*'Board size'!$B$12,"yes","NO: too big") | C30: =IF('Board size'!$B$33>=C15+2*'Board size'!$B$12,"yes","NO: too big") | D30: =IF('Board size'!$B$33>=D15+2*'Board size'!$B$12,"yes","NO: too big") | E30: =IF('Board size'!$B$33>=E15+2*'Board size'!$B$12,"yes","NO: too big")
A31: Shortcomings | B31: Smallest and thinnest, but the least energy. NOT in stock at Mouser (factory order, lead time unknown). $13.87 each: the priciest per mWh. | C31: Good thin option. NOT in stock at Mouser (factory order). The 21 x 12.8 mm size is the widest of the thin cells. | D31: Best energy for the size, but 5.5 mm thick (the thickest) and only 3 in stock at Mouser. 'Available in USA only' shipping flag. | E31: Most energy, but 27.5 x 20.5 mm: its diagonal is 34 mm, which forces a larger board. NOT in stock at Mouser. Connector version, not bare wires.
A32: How well verified | B32: Dimensions, weight and charge limits VERIFIED (Renata datasheet via Conrad). Mouser price/stock VERIFIED today. | C32: Datasheet VERIFIED (Conrad copy). Mouser price/stock VERIFIED today. | D32: Mouser page VERIFIED today (3 in stock, $12.22, 24 x 10 x 5.5 mm, 0-45 C). Datasheet from Renata. | E32: Mouser price/stock VERIFIED today. Dimensions and charge limit are from an unopened datasheet excerpt (UNVERIFIED).

Sheet Battery options
A1: Battery options, connections and retention (what we buy and install ourselves: JLCPCB does not sell LiPo cells)
A2: Sources: Mouser/Conrad/Renata datasheets (VERIFIED where marked); hobby-shop listings found by web search 2026-10-09 (UNVERIFIED: sizes, stock and prices change and listings disagree). 'Smallest board' = result of plan_board.py with the medium (KXOB25) / 15 mm (AM-1606C) cell, VQFN MCU, 0.5 mm edge safety, cells soldered to pads.
A4: Option | B4: Cells | C4: Capacity total (mAh) | D4: Size each L x W x T (mm) | E4: Protected? | F4: Termination | G4: Price (USD each) | H4: Stock / source | I4: Smallest board, KXOB25 (MCU front / MCU back OK) | J4: Smallest board, AM-1606C (MCU front / MCU back OK) | K4: How well verified | L4: Shortcomings
A5: Renata ICP501022UPM | B5: 1 | C5: 80 | D5: 24 x 10 x 5.5 | E5: Yes | F5: Wire leads AWG30 | G5: 12.22 | H5: Mouser 3 in stock | I5: 36 mm | J5: 40.5 mm (older run, TQFP MCU) | K5: Datasheet + Mouser page VERIFIED | L5: Thickest (5.5 mm); 3 in stock; single cell sits in the middle (rocking point).
A6: Renata ICP331319PM x2 | B6: 2 | C6: 100 | D6: 21 x 12.8 x 3.7 | E6: Yes (each) | F6: Wire leads AWG30 | G6: 12.21 | H6: Mouser 0 (factory order) | I6: 37 / 37 mm | J6: 43 / 42 mm | K6: Datasheet + Mouser VERIFIED | L6: Not stocked; about $24 for two; two cells to match and solder.
A7: Renata ICP341018PM x2 | B7: 2 | C7: 70 | D7: 19.5 x 10.2 x 3.7 | E7: Yes (each) | F7: Wire leads AWG30 | G7: 13.87 | H7: Mouser 0 (factory order); Conrad ~EUR 14 | I7: 37 mm | J7: n/a | K7: Datasheet + Mouser VERIFIED | L7: Least energy; priciest per mAh.
A8: Generic LP401230 x2 | B8: 2 | C8: 200 | D8: 30 x 12 x 4 (listing: 100-110 mAh each) | E8: Varies by seller | F8: Wires or JST-PH | G8: n/a | H8: BerryBase / eBay DE (no US shipping on one listing) | I8: 42 / 42 mm | J8: 46 / 46 mm | K8: UNVERIFIED: capacity listings disagree | L8: Long cells need a wider board; two of them need 42 mm+; quality varies.
A9: Generic LP401230 x1 | B9: 1 | C9: 100 | D9: 30 x 12 x 4 | E9: Varies by seller | F9: Wires or JST-PH | G9: n/a | H9: as above | I9: 37 / 36 mm | J9: 43 / 42 mm | K9: UNVERIFIED | L9: Single cell back in the middle.
A10: Generic LP402025 (e.g. Adafruit 1317 150 mAh) | B10: 1 | C10: 150 | D10: 27 x 20 x 4 (UNVERIFIED) | E10: Yes | F10: JST-PH plug (cut off or use) | G10: 5.95 | H10: Adafruit; one distributor shows stock conflicts | I10: 37 / 37 mm | J10: 43 / 42 mm | K10: UNVERIFIED (search snippets) | L10: Single big cell in the middle (rocking); two do not fit under 48 mm.
A11: Adafruit 100 mAh (1570) / SparkFun 110 mAh (PRT-13853) | B11: 1 | C11: 100 | D11: about 30 x 12 x 4 (UNVERIFIED) | E11: Yes | F11: JST-PH plug | G11: 11.60 / 7.53 | H11: Marked retired or backorder by some sellers | I11: n/a | J11: n/a | K11: UNVERIFIED | L11: Stock unclear.
A12: LIR2032 coin | B12: 1 | C12: 40 | D12: 20 dia x 3.2 | E12: NO | F12: Holder or solder tabs | G12: n/a | H12: Many sellers (EEMB, RS, Loopacell...) | I12: about 40 mm | J12: about 44 mm | K12: Size/voltage VERIFIED in 3 datasheets; no protection found | L12: Half the energy; needs a protection part; holder adds bulk.
A13: TinyCircuits 70 mAh (ASR00011) | B13: 2 | C13: 140 | D13: 15 x 15 x 5 (+/-3, +/-2, +/-0.5) | E13: Yes | F13: JST SHR-02V-S-B plug, 25 mm wires (matches our header) | G13: n/a (not fetched) | H13: TinyCircuits shop; Mouser carries other TinyCircuits cells | I13: 46 mm (strict) | J13: 46 mm (strict) | K13: Size from a search summary; plug VERIFIED on the 150 mAh page | L13: Fat (5 mm); two of them are only 140 mAh.
A14: TinyCircuits 150 mAh (ASR00003) | B14: 1 | C14: 150 | D14: 20 x 20 x 5 (+/-3, +/-2, +/-0.5) | E14: Yes | F14: JST SHR-02V-S-B plug, 25 mm wires | G14: 4.95 | H14: TinyCircuits shop; Mouser datasheet exists | I14: single cell: fits | J14: single cell: fits | K14: TinyCircuits page VERIFIED (size, plug, price, protection, certs) | L14: Square 5 mm cell in the middle again; two do not fit under 48 mm.
A15: Generic LP301030 x2 (3.0 x 10 x 30) | B15: 2 | C15: 140 | D15: 30.5 x 10.2 x 3.2 | E15: PCM included on some listings | F15: Wires (a seller can fit JST-SH to order: UNVERIFIED) | G15: about 2-3 (listings) | H15: Amazon, eBay, Alibaba makers | I15: 45 mm (strict) | J15: 45 mm (strict) | K15: UNVERIFIED: capacity 60-100 mAh depending on seller; no manufacturer datasheet found | L15: Thinnest option (3.2 mm); capacity and PCM vary by listing.
A16: Generic LP401030 x2 (4.0 x 10 x 30) | B16: 2 | C16: 180 | D16: 30 x 10 x 4 | E16: Yes (PCM) | F16: Wires | G16: n/a | H16: LiPol and many makers | I16: 44 mm (strict) | J16: 44 mm (strict) | K16: LiPol datasheet exists (90 mAh, charge <= 45 mA); stock not checked | L16: Slow charge limit (45 mA).
A17: Electrokit 220 mAh with JST-SH | B17: 1 | C17: 220 | D17: 36.5 x 21 x 4.5 | E17: Yes | F17: 150 mm AWG24 cable + JST-SH plug | G17: n/a | H17: Electrokit (EU/Nordics only) | I17: does not fit | J17: does not fit | K17: UNVERIFIED | L17: Too big for the back.
A19: Connections (what joins the cell to the board)
A20: Option | B20: Part | C20: JLCPCB assembles it? | D20: Colour | E20: Size | F20: Pros | G20: Cons | H20: Verified?
A21: JST-SH header (1 mm), our current choice | B21: SM02B-SRSS-TB(LF)(SN), JLCPCB C160402; mating plug JST SHR-02V-S-B | C21: YES: 27,798 in stock. (Use C160402; the plain listing C18337480 has 0 stock.) | D21: Not verified: check the JST drawing for the housing colour | E21: tiny, about 3 mm tall | F21: Smallest plug-in; assembler places it; TinyCircuits cells and Electrokit cells already ship with this plug; hand-swap with no soldering iron. | G21: Most hobby cells ship with PH plugs; generic sellers may fit SH to order (UNVERIFIED). Opening direction on the boards is unverified against the JST drawing. | H21: JLCPCB stock VERIFIED
A22: Screw or spring wire terminal (for swapping cells with no iron) | B22: Phoenix PTSM / 1771091 (2.5 mm pitch, SMD spring-cage, screwless); smallest screw terminals are 2.54 mm pitch | C22: yes (SMD) but height NOT verified | D22: typically black/green (UNVERIFIED) | E22: likely 6+ mm tall | F22: Tool-free swap of bare wires. | G22: Much bigger than the 3-4 mm JST-SH; needs bare wire ends; heavy for a watch. | H22: UNVERIFIED (datasheet blocked)
A23: Solder the cell wires to pads | B23: no part (2 small pads per cell, drawn on the boards) | C23: pads yes; wires are a manual step | D23: n/a | E23: flat | F23: Most elegant and thinnest; no plastic at all; no PH/SH mismatch. | G23: Hand soldering near a cell; needs strain relief (tape/foam). | H23: reasoning
A24: JST-PH header (2 mm) | B24: B2B-PH-SM4 family (not checked) | C24: likely yes (not checked) | D24: typically white/natural (UNVERIFIED); black variants exist (UNVERIFIED) | E24: about 6 mm tall | F24: Matches most hobby cells with no cutting. | G24: Bigger, taller, white by default. | H24: UNVERIFIED
A26: Holding the cells down
A27: Option | B27: How | C27: Interferes with the LED band / front parts? | D27: Verdict
A28: Foam tape under each cell + polyimide (Kapton) tape over it | B28: Tape bridges onto bare board next to the cell (yellow dashed zone on the diagrams). | C28: No: nothing goes through the board. | D28: USE for prototypes.
A29: Zip ties through board slots | B29: A tie needs a slot on each side of the cell; the outer slot would sit under the LED band. | C29: YES: slots land where the LEDs and their traces are. | D29: AVOID.
A30: Thin metal shield over each cell (or both) | B30: Custom folded 0.2-0.3 mm stainless sheet or a standard soldered shield frame/lid, soldered to ground pads or glued; leaves a small gap over the cell (foam). | C30: No if its pads sit on the dashed zone. | D30: GOOD later; no specific product verified yet.
A31: Case with a 1 mm bumper | B31: Wrap-under case; strap through the board slots. | C31: No. | D31: LATER (not for first prototypes).

Sheet Solar
A1: Solar: light units, cell power, and daily harvest
A2: Unit chain: lux -> W/m2 (divide by lux-per-W/m2) -> mW/cm2 (divide by 10) -> suns (divide W/m2 by 1000). Indoor LED/fluorescent ~300 lux per W/m2, daylight ~120 (ESTIMATES, see solar-watch-evidence.md).
A4: Light condition | B4: Lux | C4: Lux per W/m2 | D4: W/m2 | E4: mW/cm2 | F4: Suns | G4: Mono-Si low-light derating (vs 1 sun) | H4: Office hours/day | I4: Commuter hours/day | J4: Outdoor hours/day | K4: AM-1606C power (mW) | L4: KXOB25-07X1TF power (mW) | M4: KXOB081K06TF power (mW)
A5: Dim indoor (home) | B5: 200 | C5: 300 | D5: =B5/C5 | E5: =D5/10 | F5: =D5/1000 | G5: =4.4/18.4 | H5: 6 | I5: 5 | J5: 3 | K5: =IF($B5<=1000,$E$22/1000*($E5/$E$5),$F$22*$E5*$B$22) | L5: =$D$23*($E5/100)*$G5 | M5: =$D$24*($E5/100)*$G5
A6: Desk | B6: 500 | C6: 300 | D6: =B6/C6 | E6: =D6/10 | F6: =D6/1000 | G6: =7/18.4 | H6: 6 | I6: 4 | J6: 1 | K6: =IF($B6<=1000,$E$22/1000*($E6/$E$5),$F$22*$E6*$B$22) | L6: =$D$23*($E6/100)*$G6 | M6: =$D$24*($E6/100)*$G6
A7: Window | B7: 1000 | C7: 120 | D7: =B7/C7 | E7: =D7/10 | F7: =D7/1000 | G7: =11/18.4 | H7: 1 | I7: 1 | J7: 0 | K7: =IF($B7<=1000,$E$22/1000*($E7/$E$5),$F$22*$E7*$B$22) | L7: =$D$23*($E7/100)*$G7 | M7: =$D$24*($E7/100)*$G7
A8: Overcast / shade | B8: 5000 | C8: 120 | D8: =B8/C8 | E8: =D8/10 | F8: =D8/1000 | G8: =15/18.4 | H8: 0.7 | I8: 1.5 | J8: 3 | K8: =IF($B8<=1000,$E$22/1000*($E8/$E$5),$F$22*$E8*$B$22) | L8: =$D$23*($E8/100)*$G8 | M8: =$D$24*($E8/100)*$G8
A9: Bright shade | B9: 20000 | C9: 120 | D9: =B9/C9 | E9: =D9/10 | F9: =D9/1000 | G9: =17/18.4 | H9: 0 | I9: 0 | J9: 3 | K9: =IF($B9<=1000,$E$22/1000*($E9/$E$5),$F$22*$E9*$B$22) | L9: =$D$23*($E9/100)*$G9 | M9: =$D$24*($E9/100)*$G9
A10: Partial sun | B10: 30000 | C10: 120 | D10: =B10/C10 | E10: =D10/10 | F10: =D10/1000 | G10: =17.5/18.4 | H10: 0.3 | I10: 1 | J10: 0 | K10: =IF($B10<=1000,$E$22/1000*($E10/$E$5),$F$22*$E10*$B$22) | L10: =$D$23*($E10/100)*$G10 | M10: =$D$24*($E10/100)*$G10
A11: Sunny | B11: 50000 | C11: 120 | D11: =B11/C11 | E11: =D11/10 | F11: =D11/1000 | G11: =18/18.4 | H11: 0 | I11: 0 | J11: 2 | K11: =IF($B11<=1000,$E$22/1000*($E11/$E$5),$F$22*$E11*$B$22) | L11: =$D$23*($E11/100)*$G11 | M11: =$D$24*($E11/100)*$G11
A12: Reference: 1 full sun | B12: 120000 | C12: 120 | D12: =B12/C12 | E12: =D12/10 | F12: =D12/1000
A13: Hours per day at each lux band are ESTIMATES from the research report; the rest of the day counts as zero light. Derating = mono-Si efficiency at that light divided by its 1-sun efficiency (UNVERIFIED snippets).
A15: Profile | B15: Fraction of the time the face is uncovered by a sleeve
A16: Office worker | B16: 0.7 | C16: ESTIMATES: no published source.
A17: Commuter | B17: 0.6
A18: Outdoor enthusiast | B18: 0.8
A21: Cell | B21: Footprint area (cm2) | C21: Type | D21: Power at 1 sun (mW) | E21: Measured at 200 lux (uW) | F21: Outdoor efficiency (a-Si only) | G21: Size (mm) | H21: Status | I21: Length (mm) | J21: Width (mm) | K21: Thickness (mm) | L21: Buy it
A22: AM-1606C | B22: =1.5*1.5 | C22: a-Si (glass) | E22: 8.84 | F22: 0.045 | G22: 15 x 15 x 0.7 | H22: 200 lux VERIFIED (Panasonic catalog: 2.6 V x 3.4 uA). Outdoor efficiency 4.5% is an ESTIMATE (similar Amorton outdoor cells run 3.6-5.4%). | I22: 15 | J22: 15 | K22: 0.9 | L22: DigiKey (DISCONTINUED there, 640 left)
A23: KXOB25-07X1TF | B23: =1.135*0.8 | C23: mono-Si | D23: 14.3 | G23: 11.35 x 8 x 1.2 | H23: 1-sun power VERIFIED (Anysolar datasheet, preliminary). Low-light power is an ESTIMATE. | I23: 11.35 | J23: 8 | K23: 1.2 | L23: Anysolar datasheet (no live stock found)
A24: KXOB081K06TF (yours) | B24: =2.3*2.5 | C24: mono-Si | D24: 105.9 | G24: 23 x 25 x 1.2 | H24: 1-sun power VERIFIED (Anysolar datasheet, preliminary). Low-light power is an ESTIMATE. | I24: 23 | J24: 25 | K24: 1.2 | L24: DigiKey ($6.59, 2,754 on 10/06)
A25: AM-1606C thickness: Panasonic's catalog says 0.7 mm, DigiKey's listing says 0.9 mm; the larger value is used here.
A27: Harvest per day (mWh) | B27: Office worker | C27: Commuter | D27: Outdoor enthusiast
A28: AM-1606C | B28: =SUMPRODUCT($H$5:$H$11,$K$5:$K$11)*Inputs!$B$39*$B$16*Inputs!$B$40*Inputs!$B$41*Inputs!$B$42 | C28: =SUMPRODUCT($I$5:$I$11,$K$5:$K$11)*Inputs!$B$39*$B$17*Inputs!$B$40*Inputs!$B$41*Inputs!$B$42 | D28: =SUMPRODUCT($J$5:$J$11,$K$5:$K$11)*Inputs!$B$39*$B$18*Inputs!$B$40*Inputs!$B$41*Inputs!$B$42
A29: KXOB25-07X1TF | B29: =SUMPRODUCT($H$5:$H$11,$L$5:$L$11)*Inputs!$B$39*$B$16*Inputs!$B$40*Inputs!$B$41*Inputs!$B$42 | C29: =SUMPRODUCT($I$5:$I$11,$L$5:$L$11)*Inputs!$B$39*$B$17*Inputs!$B$40*Inputs!$B$41*Inputs!$B$42 | D29: =SUMPRODUCT($J$5:$J$11,$L$5:$L$11)*Inputs!$B$39*$B$18*Inputs!$B$40*Inputs!$B$41*Inputs!$B$42
A30: KXOB081K06TF (yours) | B30: =SUMPRODUCT($H$5:$H$11,$M$5:$M$11)*Inputs!$B$39*$B$16*Inputs!$B$40*Inputs!$B$41*Inputs!$B$42 | C30: =SUMPRODUCT($I$5:$I$11,$M$5:$M$11)*Inputs!$B$39*$B$17*Inputs!$B$40*Inputs!$B$41*Inputs!$B$42 | D30: =SUMPRODUCT($J$5:$J$11,$M$5:$M$11)*Inputs!$B$39*$B$18*Inputs!$B$40*Inputs!$B$41*Inputs!$B$42
A32: Harvest = sum over light bands of (hours x cell power) x wrist x sleeve x optical x harvester x charge efficiency. Compare with the daily load on the 'Power budget' tab.

Sheet Parts
A1: Parts list for the current picks, with cost and every link
A2: Quantities follow your picks on Inputs. Unit price uses the 'Where to buy' choice (row 61). DigiKey/Mouser/JLCPCB data checked 2026-10-08 unless noted. 'n/a' means I did not fetch it. Prices are at the quantity shown (1 watch); volume pricing is lower.
A4: Part | B4: Qty | C4: DigiKey / Mouser part | D4: DigiKey / Mouser stock | E4: DigiKey / Mouser price (USD) | F4: JLCPCB part | G4: JLCPCB stock | H4: JLCPCB price (USD) | I4: Unit price used (USD) | J4: Line cost (USD) | K4: Links | L4: Notes | M4: JLCPCB link
A5: Hour LEDs | B5: 12 | C5: =INDEX(LEDs!$B$17:$G$17,MATCH(Inputs!$B$56,LEDs!$B$4:$G$4,0)) | D5: =INDEX(LEDs!$B$18:$G$18,MATCH(Inputs!$B$56,LEDs!$B$4:$G$4,0)) | E5: =IF(ISNUMBER(INDEX(LEDs!$B$20:$G$20,MATCH(Inputs!$B$56,LEDs!$B$4:$G$4,0))),INDEX(LEDs!$B$20:$G$20,MATCH(Inputs!$B$56,LEDs!$B$4:$G$4,0)),INDEX(LEDs!$B$19:$G$19,MATCH(Inputs!$B$56,LEDs!$B$4:$G$4,0))) | F5: =INDEX(LEDs!$B$24:$G$24,MATCH(Inputs!$B$56,LEDs!$B$4:$G$4,0)) | G5: =INDEX(LEDs!$B$26:$G$26,MATCH(Inputs!$B$56,LEDs!$B$4:$G$4,0)) | H5: =INDEX(LEDs!$B$27:$G$27,MATCH(Inputs!$B$56,LEDs!$B$4:$G$4,0)) | I5: =IF(Inputs!$B$61="JLCPCB / LCSC",IF(ISNUMBER(H5),H5,IF(ISNUMBER(E5),E5,0)),IF(ISNUMBER(E5),E5,IF(ISNUMBER(H5),H5,0))) | J5: =B5*I5 | K5: see the LEDs tab | L5: ="Pick: "&Inputs!$B$56
A6: Minute LEDs | B6: 60 | C6: =INDEX(LEDs!$B$17:$G$17,MATCH(Inputs!$B$57,LEDs!$B$4:$G$4,0)) | D6: =INDEX(LEDs!$B$18:$G$18,MATCH(Inputs!$B$57,LEDs!$B$4:$G$4,0)) | E6: =IF(ISNUMBER(INDEX(LEDs!$B$20:$G$20,MATCH(Inputs!$B$57,LEDs!$B$4:$G$4,0))),INDEX(LEDs!$B$20:$G$20,MATCH(Inputs!$B$57,LEDs!$B$4:$G$4,0)),INDEX(LEDs!$B$19:$G$19,MATCH(Inputs!$B$57,LEDs!$B$4:$G$4,0))) | F6: =INDEX(LEDs!$B$24:$G$24,MATCH(Inputs!$B$57,LEDs!$B$4:$G$4,0)) | G6: =INDEX(LEDs!$B$26:$G$26,MATCH(Inputs!$B$57,LEDs!$B$4:$G$4,0)) | H6: =INDEX(LEDs!$B$27:$G$27,MATCH(Inputs!$B$57,LEDs!$B$4:$G$4,0)) | I6: =IF(Inputs!$B$61="JLCPCB / LCSC",IF(ISNUMBER(H6),H6,IF(ISNUMBER(E6),E6,0)),IF(ISNUMBER(E6),E6,IF(ISNUMBER(H6),H6,0))) | J6: =B6*I6 | K6: see the LEDs tab | L6: ="Pick: "&Inputs!$B$57
A7: Second LEDs | B7: 60 | C7: =INDEX(LEDs!$B$17:$G$17,MATCH(Inputs!$B$58,LEDs!$B$4:$G$4,0)) | D7: =INDEX(LEDs!$B$18:$G$18,MATCH(Inputs!$B$58,LEDs!$B$4:$G$4,0)) | E7: =IF(ISNUMBER(INDEX(LEDs!$B$20:$G$20,MATCH(Inputs!$B$58,LEDs!$B$4:$G$4,0))),INDEX(LEDs!$B$20:$G$20,MATCH(Inputs!$B$58,LEDs!$B$4:$G$4,0)),INDEX(LEDs!$B$19:$G$19,MATCH(Inputs!$B$58,LEDs!$B$4:$G$4,0))) | F7: =INDEX(LEDs!$B$24:$G$24,MATCH(Inputs!$B$58,LEDs!$B$4:$G$4,0)) | G7: =INDEX(LEDs!$B$26:$G$26,MATCH(Inputs!$B$58,LEDs!$B$4:$G$4,0)) | H7: =INDEX(LEDs!$B$27:$G$27,MATCH(Inputs!$B$58,LEDs!$B$4:$G$4,0)) | I7: =IF(Inputs!$B$61="JLCPCB / LCSC",IF(ISNUMBER(H7),H7,IF(ISNUMBER(E7),E7,0)),IF(ISNUMBER(E7),E7,IF(ISNUMBER(H7),H7,0))) | J7: =B7*I7 | K7: see the LEDs tab | L7: ="Pick: "&Inputs!$B$58
A8: MCU AVR128DB48-I/PT | B8: 1 | C8: 150-AVR128DB48-I/PT-ND | D8: 217 | E8: 2.16 | F8: C1019766 | G8: 60 | H8: 5.38 | I8: =IF(Inputs!$B$61="JLCPCB / LCSC",IF(ISNUMBER(H8),H8,IF(ISNUMBER(E8),E8,0)),IF(ISNUMBER(E8),E8,IF(ISNUMBER(H8),H8,0))) | J8: =B8*I8 | K8: DigiKey | L8: Only 60 at JLCPCB and 217 at DigiKey: thin supply for a prototype run. | M8: JLCPCB
A9: Motion sensor BMI270 | B9: =IF(ISNUMBER(SEARCH("BMI270",Inputs!$B$32&Inputs!$B$51)),1,0) | C9: 828-1091-2-ND | D9: 50792 | E9: 4.23 | F9: C2836813 | G9: 7628 | H9: 2.64 | I9: =IF(Inputs!$B$61="JLCPCB / LCSC",IF(ISNUMBER(H9),H9,IF(ISNUMBER(E9),E9,0)),IF(ISNUMBER(E9),E9,IF(ISNUMBER(H9),H9,0))) | J9: =B9*I9 | K9: DigiKey | M9: JLCPCB
A10: Motion sensor BMA400 | B10: =IF(ISNUMBER(SEARCH("BMA400",Inputs!$B$32&Inputs!$B$51)),1,0) | C10: 828-1081-2-ND | D10: 0 | E10: 2.48 | F10: not checked | G10: n/a | H10: n/a | I10: =IF(Inputs!$B$61="JLCPCB / LCSC",IF(ISNUMBER(H10),H10,IF(ISNUMBER(E10),E10,0)),IF(ISNUMBER(E10),E10,IF(ISNUMBER(H10),H10,0))) | J10: =B10*I10 | K10: DigiKey | L10: ZERO stock at DigiKey US on every listing.
A11: Motion sensor LIS2DW12 | B11: =IF(ISNUMBER(SEARCH("LIS2DW12",Inputs!$B$32)),1,0) | C11: 497-17718-2-ND | D11: 0 | E11: 1.38 | F11: C189624 | G11: 19750 | H11: 1.19 | I11: =IF(Inputs!$B$61="JLCPCB / LCSC",IF(ISNUMBER(H11),H11,IF(ISNUMBER(E11),E11,0)),IF(ISNUMBER(E11),E11,IF(ISNUMBER(H11),H11,0))) | J11: =B11*I11 | K11: DigiKey | L11: In stock at JLCPCB only. | M11: JLCPCB
A12: Charger MCP73831T-2ACI/OT (Variant A) | B12: =IF(Inputs!$B$60="A: pad-charged",1,0) | C12: MCP73831T-2ACI/OTTR-ND | D12: 33567 | E12: 0.76 | F12: C424093 | G12: 5708 | H12: 0.79 | I12: =IF(Inputs!$B$61="JLCPCB / LCSC",IF(ISNUMBER(H12),H12,IF(ISNUMBER(E12),E12,0)),IF(ISNUMBER(E12),E12,IF(ISNUMBER(H12),H12,0))) | J12: =B12*I12 | K12: DigiKey | L12: JLCPCB figures are from 2026-10-05 (not re-checked). | M12: JLCPCB
A13: 3.3 V LDO MCP1700T-3302E/TT (Variant A) | B13: =IF(Inputs!$B$60="A: pad-charged",1,0) | C13: MCP1700T3302ETTTR-ND | D13: 0 | E13: 0.51 | F13: C39051 | G13: n/a | H13: n/a | I13: =IF(Inputs!$B$61="JLCPCB / LCSC",IF(ISNUMBER(H13),H13,IF(ISNUMBER(E13),E13,0)),IF(ISNUMBER(E13),E13,IF(ISNUMBER(H13),H13,0))) | J13: =B13*I13 | K13: DigiKey | L13: Zero stock at DigiKey; LCSC stock not checked. | M13: JLCPCB
A14: Harvester BQ25570RGRR (Variant B) | B14: =IF(Inputs!$B$60="B: solar harvester",1,0) | C14: 296-39934-2-ND | D14: 8455 | E14: 8.87 | F14: C506250 | G14: 476 | H14: 5.82 | I14: =IF(Inputs!$B$61="JLCPCB / LCSC",IF(ISNUMBER(H14),H14,IF(ISNUMBER(E14),E14,0)),IF(ISNUMBER(E14),E14,IF(ISNUMBER(H14),H14,0))) | J14: =B14*I14 | K14: DigiKey | L14: Needs a custom footprint (RGR package) and a protected LiPo (UV cut-off fixed at 1.95 V). | M14: JLCPCB
A15: 32.768 kHz crystal ABS07-32.768KHZ-T | B15: 1 | C15: 535-9542-2-ND | D15: 525316 | E15: 0.61 | F15: C130253 | G15: n/a | H15: 0.73 | I15: =IF(Inputs!$B$61="JLCPCB / LCSC",IF(ISNUMBER(H15),H15,IF(ISNUMBER(E15),E15,0)),IF(ISNUMBER(E15),E15,IF(ISNUMBER(H15),H15,0))) | J15: =B15*I15 | K15: DigiKey | L15: JLCPCB price estimated from the 2026-10-05 BOM match; stock not re-checked. | M15: JLCPCB
A16: JST SM02B-SRSS-TB(LF)(SN) battery connector | B16: 1 | C16: 455-SM02B-SRSS-TBTR-ND | D16: 66088 | E16: n/a | F16: C160402 | G16: 27798 | H16: n/a | I16: =IF(Inputs!$B$61="JLCPCB / LCSC",IF(ISNUMBER(H16),H16,IF(ISNUMBER(E16),E16,0)),IF(ISNUMBER(E16),E16,IF(ISNUMBER(H16),H16,0))) | J16: =B16*I16 | K16: DigiKey | L16: Use the (LF)(SN) listing C160402 (27,798 in stock 2026-10-09); the plain SM02B-SRSS-TB listing C18337480 has 0 stock. | M16: JLCPCB
A17: Buttons TS21-34-035-BK-260-SMT-TR | B17: 2 | C17: 2223-TS21-34-035-BK-260-SMT-TR-ND | D17: 39050 | E17: n/a | F17: not matched | G17: n/a | H17: n/a | I17: =IF(Inputs!$B$61="JLCPCB / LCSC",IF(ISNUMBER(H17),H17,IF(ISNUMBER(E17),E17,0)),IF(ISNUMBER(E17),E17,IF(ISNUMBER(H17),H17,0))) | J17: =B17*I17 | K17: DigiKey | L17: Price not fetched; stock from the 10/06 list page. KiCad footprint used is a generic KMR2.
A18: Small passives (about $0.02 each) | B18: =IF(Inputs!$B$60="A: pad-charged",20,34) | C18: generic | D18: n/a | E18: 0.02 | F18: generic | G18: n/a | H18: 0.02 | I18: =IF(Inputs!$B$61="JLCPCB / LCSC",IF(ISNUMBER(H18),H18,IF(ISNUMBER(E18),E18,0)),IF(ISNUMBER(E18),E18,IF(ISNUMBER(H18),H18,0))) | J18: =B18*I18 | L18: ESTIMATE.
A19: Solar cell (Variant B) | B19: =IF(Inputs!$B$60="B: solar harvester",1,0) | C19: =CHOOSE(MATCH(Inputs!B37,Solar!$A$22:$A$24,0),"11-AM-1606C-ND","not at DigiKey","2994-KXOB081K06TF-TR-ND") | D19: =CHOOSE(MATCH(Inputs!B37,Solar!$A$22:$A$24,0),640,"n/a",2754) | E19: =CHOOSE(MATCH(Inputs!B37,Solar!$A$22:$A$24,0),3.14,"n/a",6.59) | F19: - | G19: - | H19: - | I19: =IF(Inputs!$B$61="JLCPCB / LCSC",IF(ISNUMBER(H19),H19,IF(ISNUMBER(E19),E19,0)),IF(ISNUMBER(E19),E19,IF(ISNUMBER(H19),H19,0))) | J19: =B19*I19 | K19: see Solar tab for each cell | L19: AM-1606C is discontinued at DigiKey; KXOB25-07X1TF has no live stock found (ask Anysolar); the price shown for it is n/a.
A20: Battery (picked) | B20: 1 | C20: =INDEX(Batteries!$B$21:$E$21,MATCH(Inputs!B59,Batteries!$B$4:$E$4,0)) | D20: =INDEX(Batteries!$B$22:$E$22,MATCH(Inputs!B59,Batteries!$B$4:$E$4,0)) | E20: =INDEX(Batteries!$B$23:$E$23,MATCH(Inputs!B59,Batteries!$B$4:$E$4,0)) | F20: - | G20: - | H20: - | I20: =IF(Inputs!$B$61="JLCPCB / LCSC",IF(ISNUMBER(H20),H20,IF(ISNUMBER(E20),E20,0)),IF(ISNUMBER(E20),E20,IF(ISNUMBER(H20),H20,0))) | J20: =B20*I20 | K20: Renata ICP at Mouser | L20: Mouser is the only source found; JLCPCB does not stock Renata cells.
A21: Bare PCB, per watch (placeholder) | B21: 1 | C21: - | D21: - | E21: =61.65/5 | F21: - | G21: - | H21: =61.65/5 | I21: =IF(Inputs!$B$61="JLCPCB / LCSC",IF(ISNUMBER(H21),H21,IF(ISNUMBER(E21),E21,0)),IF(ISNUMBER(E21),E21,IF(ISNUMBER(H21),H21,0))) | J21: =B21*I21 | L21: ESTIMATE from the RGB board's JLCPCB quote ($61.65 for 5, shipping extra); the single-colour board has not been quoted.
A22: TOTAL for one watch (USD) | J22: =SUM(J5:J21)
A23: Same for 5 watches (USD, no volume discount) | J23: =5*J22
A24: Parts with no price fetched are counted as $0, so the total is a floor.

Sheet Board size
A1: How big does the board have to be? (round board with the LED rings outside the electronics)
A2: The board is the largest of four demands: (1) the LED rings themselves, (2) a free centre on the FRONT big enough for the solar cell (Variant B), (3) enough BACK area for every component and the battery, (4) room for the battery's diagonal. The strap lugs sit outside this circle.
A4: Rules you can change
A5: LED spacing around a ring (copper gap between neighbours, mm) | B5: 0.5 | C5: 0.5 = the default used for the ring layouts.
A6: Gap between rings, for traces (mm) | B6: 0.8
A7: Outer LED edge to board edge (mm) | B7: 1
A8: Clearance around the solar cell inside the free centre (mm) | B8: 0.3
A9: Extra free centre wanted when there is no solar cell (mm diameter) | B9: 0
A10: Routing and keep-out overhead on the back (x the sum of courtyards) | B10: 1.3 | C10: ESTIMATES (back-side packing).
A11: Fraction of the back circle that parts can actually fill | B11: 0.6
A12: Battery edge margin to the board edge (mm) | B12: 1.5
A14: 1. The LED rings (closed-form version of the ring generator)
A15: Ring | B15: LED pick | C15: Pad length (mm) | D15: Pad width (mm) | E15: LEDs in ring | F15: Min ring radius from LED spacing (mm)
A16: Hour (inner) | B16: =Inputs!$B$56 | C16: =INDEX(LEDs!$B$9:$G$9,MATCH(Inputs!$B$56,LEDs!$B$4:$G$4,0)) | D16: =INDEX(LEDs!$B$10:$G$10,MATCH(Inputs!$B$56,LEDs!$B$4:$G$4,0)) | E16: 12 | F16: =(D16+$B$5)/(2*SIN(PI()/E16))
A17: Minute (middle) | B17: =Inputs!$B$57 | C17: =INDEX(LEDs!$B$9:$G$9,MATCH(Inputs!$B$57,LEDs!$B$4:$G$4,0)) | D17: =INDEX(LEDs!$B$10:$G$10,MATCH(Inputs!$B$57,LEDs!$B$4:$G$4,0)) | E17: 60 | F17: =(D17+$B$5)/(2*SIN(PI()/E17))
A18: Second (outer) | B18: =Inputs!$B$58 | C18: =INDEX(LEDs!$B$9:$G$9,MATCH(Inputs!$B$58,LEDs!$B$4:$G$4,0)) | D18: =INDEX(LEDs!$B$10:$G$10,MATCH(Inputs!$B$58,LEDs!$B$4:$G$4,0)) | E18: 60 | F18: =(D18+$B$5)/(2*SIN(PI()/E18))
A19: Ring thickness on each side of the free centre (mm) | B19: =B7+C18+C17+C16+2*B6
A20: Smallest board radius from ring 3 (seconds, outermost) | B20: =F18+B7+C18/2
A21: Smallest board radius from ring 2 (minutes) | B21: =F17+B7+C18+B6+C17/2
A22: Smallest board radius from ring 1 (hours) | B22: =F16+B7+C18+C17+2*B6+C16/2
A23: DEMAND 1: board diameter the LED rings need (mm) | B23: =2*MAX(B20,B21,B22,B19)
A25: 2. The front free centre (solar cell)
A26: Solar cell shown on the front? | B26: =IF(Inputs!B60="B: solar harvester","yes","no")
A27: Cell picked on the Inputs tab | B27: =Inputs!B37
A28: Cell diagonal (mm) | B28: =SQRT(INDEX(Solar!$I$22:$I$24,MATCH(B27,Solar!$A$22:$A$24,0))^2+INDEX(Solar!$J$22:$J$24,MATCH(B27,Solar!$A$22:$A$24,0))^2)
A29: Free centre diameter needed (mm) | B29: =IF(B26="yes",B28+2*B8,B9)
A30: DEMAND 2: board diameter for the front free centre (mm) | B30: =B29+2*B19
A32: Result
A33: FINAL BOARD DIAMETER (mm) | B33: =MAX(B23,B30,B54,B57)
A34: What sets it | B34: =IF(B33=B23,"the LED rings",IF(B33=B30,"the solar cell in the centre",IF(B33=B54,"back-side parts area","the battery diagonal")))
A35: Free centre left on the front (mm diameter) | B35: =B33-2*B19
A36: Board area (mm2) | B36: =PI()*(B33/2)^2
A38: 3. The back side: every component's keep-out area
A39: Part | B39: Courtyard W (mm) | C39: Courtyard H (mm) | D39: Quantity in this build | E39: Counted area (mm2) | F39: Source
A40: MCU AVR128DB48 (TQFP-48) | B40: 10.39 | C40: 10.39 | D40: =1 | E40: =B40*C40*D40 | F40: KiCad courtyard (VERIFIED)
A41: Motion sensor BMI270 (LGA-14) | B41: =Sensors!B7 | C41: =Sensors!B8 | D41: =IF(ISNUMBER(SEARCH("BMI270",Inputs!$B$32&Inputs!$B$51)),1,0) | E41: =B41*C41*D41 | F41: KiCad courtyard
A42: Motion sensor BMA400 (LGA-12) | B42: =Sensors!C7 | C42: =Sensors!C8 | D42: =IF(ISNUMBER(SEARCH("BMA400",Inputs!$B$32&Inputs!$B$51)),1,0) | E42: =B42*C42*D42 | F42: KiCad courtyard
A43: Motion sensor LIS2DW12 (LGA-12) | B43: =Sensors!D7 | C43: =Sensors!D8 | D43: =IF(ISNUMBER(SEARCH("LIS2DW12",Inputs!$B$32&Inputs!$B$51)),1,0) | E43: =B43*C43*D43 | F43: KiCad courtyard
A44: 32.768 kHz crystal (3215) | B44: 4.09 | C44: 2.39 | D44: =1 | E44: =B44*C44*D44 | F44: KiCad courtyard
A45: Charger MCP73831 (SOT-23-5), Variant A | B45: 4.19 | C45: 3.49 | D45: =IF(Inputs!$B$60="A: pad-charged",1,0) | E45: =B45*C45*D45 | F45: KiCad courtyard
...

Sheet Layout fit
A1: Layout fit: does everything fit around / behind the solar cell?
A2: Picture: a round board. Outer band = the three LED rings. Inside the band, the front has a free round area; Variant B puts the rectangular solar cell in its middle, leaving four curved pockets (top, bottom, left, right) for chips and buttons. The BACK of the board carries the battery and whatever does not fit on the front. All areas are keep-out areas from the 'Board size' tab (courtyards x quantity), not exact placement.
A4: Geometry (live from the Board size tab)
A5: Board diameter (mm) | B5: ='Board size'!B33
A6: LED band thickness each side (mm) | B6: ='Board size'!B19
A7: Free inner circle radius (mm) | B7: =B5/2-B6
A8: Cell picked on Inputs | B8: =Inputs!B37
A9: Cell length (mm) | B9: =INDEX(Solar!$I$22:$I$24,MATCH(B8,Solar!$A$22:$A$24,0))
A10: Cell width (mm) | B10: =INDEX(Solar!$J$22:$J$24,MATCH(B8,Solar!$A$22:$A$24,0))
A11: Solar cell on the front? (Variant B) | B11: =IF(Inputs!B60="B: solar harvester","yes","no")
A12: Cell half-diagonal (mm) | B12: =IF(B11="yes",SQRT(B9^2+B10^2)/2,0)
A13: Does the cell fit inside the free circle? | B13: =IF(B11="no","no cell",IF(B12<=B7,"yes","NO: cell corners hit the LED band"))
A14: Free front area, circle minus cell (mm2) | B14: =PI()*B7^2-IF(B11="yes",B9*B10,0)
A15: Top pocket area (mm2) | B15: =IF(B11="yes",MAX(0,B7^2*ACOS(MIN(1,B10/2/B7))-(B10/2)*SQRT(MAX(0,B7^2-(B10/2)^2))),PI()*B7^2/2) | C15: Cap above/below a rectangle that is as wide as the cell is long (rotate the cell in the layout to trade top/bottom for left/right).
A16: Bottom pocket area (mm2) | B16: =B15
A17: Left + right pockets area (mm2) | B17: =MAX(0,B14-B15-B16)
A18: Fraction of a pocket parts can actually fill | B18: ='Board size'!B11
A19: Usable front area (mm2) | B19: =B14*B18
A21: Where each part goes (1 = front pocket, 0 = back with the battery)
A22: Part | B22: Area (mm2) | C22: On the front? (1/0)
A23: ='Board size'!A40 | B23: ='Board size'!E40 | C23: 0
A24: ='Board size'!A41 | B24: ='Board size'!E41 | C24: 1
A25: ='Board size'!A42 | B25: ='Board size'!E42 | C25: 1
A26: ='Board size'!A43 | B26: ='Board size'!E43 | C26: 1
A27: ='Board size'!A44 | B27: ='Board size'!E44 | C27: 1
A28: ='Board size'!A45 | B28: ='Board size'!E45 | C28: 1
A29: ='Board size'!A46 | B29: ='Board size'!E46 | C29: 1
A30: ='Board size'!A47 | B30: ='Board size'!E47 | C30: 0
A31: ='Board size'!A48 | B31: ='Board size'!E48 | C31: 0
A32: ='Board size'!A49 | B32: ='Board size'!E49 | C32: 0
A33: ='Board size'!A50 | B33: ='Board size'!E50 | C33: 1
A34: ='Board size'!A51 | B34: ='Board size'!E51 | C34: 1
... A36: ='Board size'!A53 | B36: ='Board size'!E53 | C36: 1
A38: Result
A39: Front parts needing area (mm2, x routing overhead) | B39: =SUMPRODUCT(B23:B36,C23:C36)*'Board size'!B10
A40: Usable front area (mm2) | B40: =B19
A41: FRONT VERDICT | B41: =IF(B39<=B40,"fits ("&TEXT(B39/B40,"0%")&" full)","DOES NOT FIT: "&TEXT(B39/B40,"0%")&" of the space")
A42: Back parts + battery needing area (mm2, x routing overhead) | B42: =(SUMPRODUCT(B23:B36,1-C23:C36)+'Board size'!B56)*'Board size'!B10
A43: Usable back area (whole circle, mm2) | B43: =PI()*(B5/2)^2*'Board size'!B11
A44: BACK VERDICT | B44: =IF(B42<=B43,"fits ("&TEXT(B42/B43,"0%")&" full)","DOES NOT FIT: "&TEXT(B42/B43,"0%")&" of the space")
...

Sheet Wear and stack
A1: Wearing it: thickness, the battery on the back, and the strap
A2: Your assumption: no housing, strap through the board's slots, battery soldered to the back. This tab estimates the stack-up thickness and lists what could go wrong. Heights marked ESTIMATE are not from datasheets.
A4: Stack-up from the front to the wrist (mm)
A5: Front: tallest LED (mm) | B5: =MAX(INDEX(LEDs!$B$11:$G$11,MATCH(Inputs!B56,LEDs!$B$4:$G$4,0)),INDEX(LEDs!$B$11:$G$11,MATCH(Inputs!B57,LEDs!$B$4:$G$4,0)),INDEX(LEDs!$B$11:$G$11,MATCH(Inputs!B58,LEDs!$B$4:$G$4,0))) | C5: From the LEDs tab (heights are mostly ESTIMATES).
A6: Front: solar cell thickness (mm) if Variant B | B6: =IF(Inputs!B60="B: solar harvester",INDEX(Solar!$K$22:$K$24,MATCH(Inputs!B37,Solar!$A$22:$A$24,0)),0) | C6: From the Solar tab.
A7: Front stack above the board (mm) | B7: =MAX(B5,B6) | C7: The cell sits in the middle; the LEDs are on the rings.
A8: Board thickness (mm) | B8: 1.6 | C8: 4-layer 1.6 mm FR-4 like the first design. A 1.0 mm board is possible but changes the quote.
A9: Back: MCU height (mm) | B9: 1.2 | C9: ESTIMATE: TQFP-48 is about 1.2 mm; check the datasheet.
A10: Back: battery thickness (mm, includes swelling) | B10: =INDEX(Batteries!$B$11:$E$11,MATCH(Inputs!B59,Batteries!$B$4:$E$4,0)) | C10: From the Batteries tab.
A11: Back stack below the board (mm) | B11: =MAX(B9,B10) | C11: The battery is the tallest thing on the back.
A12: Protective film on the back, e.g. Kapton tape (mm) | B12: 0.1 | C12: Prevents skin contact with solder joints and the battery.
A13: TOTAL THICKNESS without strap (mm) | B13: =B7+B8+B11+B12 | C13: A typical wristwatch is roughly 8-12 mm thick (ESTIMATE).
A15: Concerns with a bare board on the wrist (reasoning, not testing)
A16: Concern | B16: Why it matters | C16: What to do | D16: How serious
A17: Battery between board and strap, strap against the skin | B17: Your picture. The strap becomes the cushion and the barrier: skin never touches battery or solder joints. The strap must pass through the slots BEHIND the battery. | C17: Make the slots wide enough for the strap and keep the battery inside the circle so the strap cannot press on its edge. | D17: Good plan
A18: Battery directly against the skin | B18: Possible but not advisable: LiPo cells should not be bent, squeezed or pierced, and the pouch is soft. The Renata datasheet says charge only at 0-45 C (VERIFIED); skin plus a hot day can pass 45 C. | C18: Put a film or the strap between them. Do not charge the watch while wearing it. | D18: Avoid
A19: Sweat on exposed copper and solder | B19: ENIG pads and solder joints on the back will see sweat; salt water is conductive and corrosive. 3.7 V is low, but leakage drains the battery and corrodes pads. | C19: Conformal coat the back, or cover it with film. Keep LED front dry-ish; this is not waterproof. | D19: Medium
A20: Rough solder joints and wire leads against the wrist | B20: Sharp pins/leads are uncomfortable and can cut the film over time. | C20: Round the board edges, trim leads, film or tape over the back, and keep the strap between. | D20: Medium
A21: Cell swelling | B21: Renata's own datasheet lists maximum thickness above nominal (3.7 mm vs 3.4 mm) because cells swell (VERIFIED, ICP341018PM). | C21: Leave about 0.5 mm of space behind the cell; never glue it rigidly. | D21: Medium
A22: Charging temperature | B22: Cells charge only at 0-45 C; a watch in the sun can exceed 45 C. Neither the BQ25570 nor the MCP73831 has a battery-temperature input (research report). | C22: Avoid charging in direct sun; consider adding an NTC thermistor later. | D22: Medium (solar only)
A23: Thickness | B23: Board 1.6 mm + battery 3.7-5.5 mm + film + LEDs. See the total above. | C23: A thinner battery (35 or 50 mAh) saves about 2 mm; a thinner PCB saves up to 0.6 mm. | D23: Low
A24: No housing | B24: Bumps and static discharge reach the chip directly; the MCU pin protection is basic. | C24: Add small ESD protection on the buttons (TVS) if it gets worn daily. | D24: Low
A25: Nickel in ENIG | B25: ENIG has a nickel layer under the gold; a few people react to nickel if the gold wears through against skin. | C25: Film or coat the back so nothing metal touches skin. | D25: Low

Sheet Shortcomings
A1: Every shortcoming in one place (what could go wrong with each choice)
A2: Verified on 2026-10-08 unless marked. Severity: HIGH = could block the build or change the design; MEDIUM = cost/risk to manage; LOW = minor.
A4: Choice | B4: Shortcoming | C4: Severity | D4: Evidence
